Workbook
Name nproducto: [1]NPRODUCTOS!$J$9:$U$7009

Sheet Detalle1
A1: Detalles para Suma de FRECUENCIA ANUAL DE MANTENIMIENTO - CRÍTICO/ RELEVANTE / IM≥12 / NO APLICA: CRÍTICO, AÑO INGRESO A PLAN DE MANTENIMIENTO (2023 / 2024 / 2025 / 2026): 2023
A3: SERVICIO CLÍNICO | B3: RECINTO | C3: CLASE | D3: SUBCLASE | E3: NOMBRE EQUIPO | F3: MARCA | G3: MODELO | H3: SERIE | I3: N° INVENTARIO | J3: AÑO DE ADQUISICIÓN | K3: VIDA ÚTIL | L3: VIDA ÚTIL RESIDUAL | M3: PROPIO / ARRIENDO / COMODATO | N3: ESTADO (BUENO / REGULAR / MALO / BAJA) | O3: CRÍTICO/ RELEVANTE / IM≥12 / NO APLICA | P3: EN GARANTÍA (SI / NO) | Q3: AÑO VENCIMIENTO GARANTÍA | R3: BAJO PLAN DE MANTENIMIENTO (SI / NO) | S3: AÑO INGRESO A PLAN DE MANTENIMIENTO (2023 / 2024 / 2025 / 2026) | T3: MANTENIMIENTO INTERNO O MANTENIMIENTO EXTERNO O CONTRATO | U3: NOMBRE DE PROVEEDOR O MANTENIMIENTO INTERNO | V3: ID CONVENIO DE MANTENIMIENTO / ID DE REFERENCIA / COTIZACIÓN DE REFERENCIA | W3: COSTO ANUAL DE MANTENIMIENTO SEGÚN CONVENIO / PRECIO DE REFERENCIA MANTENIMIENTO ANUAL | X3: FRECUENCIA ANUAL DE MANTENIMIENTO
A4: UTI - 9D | B4: Hospital Penco Lirquen | C4: Apoyo Terapéutico | D4: Alto Costo | E4: Ventilador mecánico no Invasivo | F4: Philips | G4: Trilogy 202 | H4: TV016091214 | I4: HPL24850 | J4: 2016 | K4: 8 | L4: 1 | M4: Propio | N4: Bueno | O4: CRÍTICO | P4: NO | R4: SI | S4: 2023 | T4: EXTERNO | U4: TDM | V4: 1057540-65-LE21 | W4: 270000 | X4: 2
A5: Ambulancia | B5: Hospital Penco Lirquen | C5: Otros | D5: Alto Costo | E5: Ambulancia | F5: Mercedes - Benz | G5: Sprinter 315 | H5: FFRG-92 | I5: HPL29456 | J5: 2019 | K5: 8 | L5: 4 | M5: Propio | N5: Bueno | O5: CRÍTICO | P5: NO | R5: SI | S5: 2023 | T5: EXTERNO | U5: N/A | X5: 2
A6: Ambulancia | B6: Hospital Penco Lirquen | C6: Otros | D6: Alto Costo | E6: Ambulancia | F6: Mercedes - Benz | G6: Sprinter 315 | H6: FFRG-94 | I6: HPL29457 | J6: 2019 | K6: 8 | L6: 4 | M6: Propio | N6: Bueno | O6: CRÍTICO | P6: NO | R6: SI | S6: 2023 | T6: EXTERNO | U6: N/A | X6: 2
A7: Ambulancia | B7: Hospital Penco Lirquen | C7: Otros | D7: Alto Costo | E7: Ambulancia | F7: Mercedes - Benz | G7: Sprinter 314 | H7: PGHF-57 | I7: HPL29451 | J7: 2020 | K7: 8 | L7: 5 | M7: Propio | N7: Bueno | O7: CRÍTICO | P7: NO | R7: SI | S7: 2023 | T7: EXTERNO | U7: N/A | X7: 2
A8: Ambulancia - 6B | B8: Hospital Penco Lirquen | C8: Monitoreo | D8: Mediano Costo | E8: Desfibrilador externo automático (DEA) | F8: Mindray | G8: BeneHeart C2 | H8: AE7-01001130 | I8: HPL30209 | J8: 2020 | K8: 8 | L8: 5 | M8: Propio | N8: Bueno | O8: CRÍTICO | P8: NO | R8: SI | S8: 2023 | T8: INTERNO | U8: TECNICO EQM HPL | X8: 2
A9: Ambulancia - 7B | B9: Hospital Penco Lirquen | C9: Monitoreo | D9: Mediano Costo | E9: Monitor ECG Baja Complejidad | F9: Nihon Kohden | G9: SVM-7260 | H9: 00292 | I9: HPL30123 | J9: 2020 | K9: 8 | L9: 5 | M9: Propio | N9: Bueno | O9: CRÍTICO | P9: NO | R9: SI | S9: 2023 | T9: INTERNO | U9: TECNICO EQM HPL | X9: 2
A10: Ambulancia - 7B | B10: Hospital Penco Lirquen | C10: Monitoreo | D10: Mediano Costo | E10: Monitor de signos vitales | F10: Mindray | G10: DPM3 | H10: DQ-18000401 | I10: HPL30239 | J10: 2015 | K10: 8 | L10: 0 | M10: Propio | N10: Bueno | O10: CRÍTICO | P10: NO | R10: SI | S10: 2023 | T10: INTERNO | U10: TECNICO EQM HPL | X10: 2
A11: Ambulancia - 7B | B11: Hospital Penco Lirquen | C11: Monitoreo | D11: Mediano Costo | E11: Monitor ECG Baja Complejidad | F11: Mindray | G11: uMEC10 | H11: KN-03065493 | I11: HPL30261 | J11: 2020 | K11: 8 | L11: 5 | M11: Propio | N11: Bueno | O11: CRÍTICO | P11: NO | R11: SI | S11: 2023 | T11: INTERNO | U11: TECNICO EQM HPL | X11: 2
A12: Ambulancia -11 | B12: Hospital Penco Lirquen | C12: Monitoreo | D12: Mediano Costo | E12: Desfibrilador externo automático (DEA) | F12: Philips | G12: Heart Start | H12: A19K-06543 | I12: HPL30200 | J12: 2020 | K12: 8 | L12: 5 | M12: Propio | N12: Bueno | O12: CRÍTICO | P12: NO | R12: SI | S12: 2023 | T12: INTERNO | U12: TECNICO EQM HPL | X12: 2
A13: UTI - 9D | B13: Hospital Penco Lirquen | C13: Apoyo Terapéutico | D13: Alto Costo | E13: Ventilador mecánico no Invasivo | F13: Philips | G13: Trilogy 202 | H13: TV016091211 | I13: HPL24776 | J13: 2016 | K13: 8 | L13: 1 | M13: Propio | N13: Bueno | O13: CRÍTICO | P13: NO | R13: SI | S13: 2023 | T13: EXTERNO | U13: TDM | V13: 1057540-65-LE21 | W13: 270000 | X13: 2
A14: UTI - 1B | B14: Hospital Penco Lirquen | C14: Apoyo Terapéutico | D14: Alto Costo | E14: Ventilador mecánico Invasivo | F14: Aeonmed | G14: VG70 | H14: XZZT14086 | I14: HPL30403 | J14: 2020 | K14: 8 | L14: 5 | M14: Préstamo | N14: Bueno | O14: CRÍTICO | P14: NO | R14: SI | S14: 2023 | T14: EXTERNO | U14: TDM | V14: 1057540-65-LE21 | W14: 407911 | X14: 2
A15: UTI - 1B | B15: Hospital Penco Lirquen | C15: Apoyo Terapéutico | D15: Alto Costo | E15: Ventilador mecánico Invasivo | F15: Aeonmed | G15: VG70 | H15: XZZT13533 | I15: .- | J15: 2021 | K15: 8 | L15: 6 | M15: Préstamo | N15: Bueno | O15: CRÍTICO | R15: SI | S15: 2023 | X15: 2
A16: BODEGA DE EQUIPOS MÉDICOS | B16: Hospital Penco Lirquen | C16: Apoyo Terapéutico | D16: Alto Costo | E16: Ventilador mecánico Invasivo | F16: Aeonmed | G16: VG70 | H16: XZZT17062 | I16: HPL30404 | J16: 2020 | K16: 8 | L16: 5 | M16: Préstamo | N16: Bueno | O16: CRÍTICO | P16: NO | R16: SI | S16: 2023 | T16: EXTERNO | V16: LIC 5 | W16: 407911 | X16: 2
A17: BODEGA DE EQUIPOS MÉDICOS - 1B | B17: Hospital Penco Lirquen | C17: Apoyo Terapéutico | D17: Alto Costo | E17: Ventilador mecánico Invasivo | F17: MECKics | G17: MV2000-EVO 5 | H17: MV2000UA1C0315 | I17: HPL30269 | J17: 2021 | K17: 8 | L17: 6 | M17: Préstamo | N17: Bueno | O17: CRÍTICO | P17: SI | R17: SI | S17: 2023 | T17: EXTERNO | V17: LIC 5 | W17: 407911 | X17: 2
A18: BODEGA DE EQUIPOS MÉDICOS - 1B | B18: Hospital Penco Lirquen | C18: Apoyo Terapéutico | D18: Alto Costo | E18: Ventilador mecánico Invasivo | F18: MECKics | G18: MV2000-EVO 5 | H18: MV2000UA1C0316 | I18: HPL30270 | J18: 2021 | K18: 8 | L18: 6 | M18: Préstamo | N18: Bueno | O18: CRÍTICO | P18: SI | R18: SI | S18: 2023 | T18: EXTERNO | V18: LIC 5 | W18: 407911 | X18: 2
A19: BODEGA DE EQUIPOS MÉDICOS - 1B | B19: Hospital Penco Lirquen | C19: Apoyo Terapéutico | D19: Alto Costo | E19: Ventilador mecánico Invasivo | F19: MECKics | G19: MV2000-EVO 5 | H19: MV2000UA1C0317 | I19: HPL30271 | J19: 2021 | K19: 8 | L19: 6 | M19: Préstamo | N19: Bueno | O19: CRÍTICO | P19: SI | R19: SI | S19: 2023 | T19: EXTERNO | V19: LIC 5 | W19: 407911 | X19: 2
A20: BODEGA DE EQUIPOS MÉDICOS - 1B | B20: Hospital Penco Lirquen | C20: Apoyo Terapéutico | D20: Alto Costo | E20: Ventilador mecánico Invasivo | F20: MECKics | G20: MV2000-EVO 5 | H20: MV2000UA1C0549 | I20: HPL30272 | J20: 2021 | K20: 8 | L20: 6 | M20: Préstamo | N20: Bueno | O20: CRÍTICO | P20: SI | R20: SI | S20: 2023 | T20: EXTERNO | V20: LIC 5 | W20: 407911 | X20: 2
A21: Bodega de Equipos Médicos - 6B | B21: Hospital Penco Lirquen | C21: Monitoreo | D21: Mediano Costo | E21: Desfibrilador externo automático (DEA) | F21: Philips | G21: Heart Start | H21: A15G-08197 | I21: HPL30196 | J21: 2015 | K21: 8 | L21: 0 | M21: Propio | N21: Bueno | O21: CRÍTICO | P21: NO | R21: SI | S21: 2023 | T21: INTERNO | U21: TECNICO EQM HPL | X21: 2
A22: UTI - 1B | B22: Hospital Penco Lirquen | C22: Apoyo Terapéutico | D22: Alto Costo | E22: Ventilador mecánico Invasivo | F22: Aeonmed | G22: VG70 | H22: XZZT11901 | I22: HPL30402 | J22: 2020 | K22: 8 | L22: 5 | M22: Préstamo | N22: Bueno | O22: CRÍTICO | P22: NO | R22: SI | S22: 2023 | T22: EXTERNO | U22: TDM | V22: LIC 5 | W22: 407911 | X22: 2
A23: UTI - 1B | B23: Hospital Penco Lirquen | C23: Apoyo Terapéutico | D23: Alto Costo | E23: Ventilador mecánico Invasivo | F23: Aeonmed | G23: VG70 | H23: XZZS27794 | I23: .- | J23: 2021 | K23: 8 | L23: 6 | M23: Préstamo | N23: Bueno | O23: CRÍTICO | R23: SI | S23: 2023 | T23: EXTERNO | X23: 2
A24: UTI - 1B | B24: Hospital Penco Lirquen | C24: Apoyo Terapéutico | D24: Alto Costo | E24: Ventilador mecánico Invasivo | F24: Philips | G24: Trilogy 100 | H24: TV11909271B | I24: HPL30385 | J24: 2020 | K24: 8 | L24: 5 | M24: Préstamo | N24: Bueno | O24: CRÍTICO | P24: NO | R24: SI | S24: 2023 | T24: EXTERNO | U24: TDM | V24: 1057540-65-LE21 | W24: 270000 | X24: 2
A25: UTI - 1B | B25: Hospital Penco Lirquen | C25: Apoyo Terapéutico | D25: Alto Costo | E25: Ventilador mecánico Invasivo | F25: MECKics | G25: MV2000-EVO 5 | H25: MV2000UA1C0551 | I25: HPL30273 | J25: 2021 | K25: 8 | L25: 6 | M25: Préstamo | N25: Bueno | O25: CRÍTICO | P25: NO | R25: SI | S25: 2023 | T25: EXTERNO | V25: LIC 5 | W25: 407911 | X25: 2
A26: UTI - 1B | B26: Hospital Penco Lirquen | C26: Monitoreo | D26: Mediano Costo | E26: Monitor desfibrilador con carro de paro | F26: Zoll | G26: Serie R ALS | H26: AF20F118297 | I26: HPL30215 | J26: 2020 | K26: 8 | L26: 5 | M26: Propio | N26: Bueno | O26: CRÍTICO | P26: NO | R26: SI | S26: 2023 | T26: INTERNO | U26: TECNICO EQM HPL | X26: 2
A27: UTI - 1B | B27: Hospital Penco Lirquen | C27: Apoyo Terapéutico | D27: Alto Costo | E27: Ventilador mecánico no Invasivo | F27: Covidien | G27: Puritan Bennet 560 | H27: 40966N0858 | I27: HPL30188 | J27: 2020 | K27: 8 | L27: 5 | M27: Préstamo | N27: Bueno | O27: CRÍTICO | P27: NO | R27: SI | S27: 2023 | T27: EXTERNO | V27: LIC 5 | W27: 1039250 | X27: 2
A28: Bodega equipos médicos - 1A | B28: Hospital Penco Lirquen | C28: Monitoreo | D28: Alto Costo | E28: Monitor ECG mediana complejidad | F28: Nihon Kohden | G28: BSM-6301K | H28: 8352 | I28: HPL29882 | J28: 2017 | K28: 8 | L28: 2 | M28: Propio | N28: Bueno | O28: CRÍTICO | P28: NO | R28: SI | S28: 2023 | T28: INTERNO | U28: TECNICO EQM HPL | X28: 2
A29: Bodega equipos médicos - 1A | B29: Hospital Penco Lirquen | C29: Monitoreo | D29: Alto Costo | E29: Monitor ECG mediana complejidad | F29: Nihon Kohden | G29: BSM-6301K | H29: 8353 | I29: HPL25047 | J29: 2017 | K29: 8 | L29: 2 | M29: Propio | N29: Bueno | O29: CRÍTICO | P29: NO | R29: SI | S29: 2023 | T29: INTERNO | U29: TECNICO EQM HPL | X29: 2
A30: Bodega equipos médicos - 1A | B30: Hospital Penco Lirquen | C30: Monitoreo | D30: Alto Costo | E30: Monitor ECG mediana complejidad | F30: Nihon Kohden | G30: BSM-6301K | H30: 8357 | I30: HPL29885 | J30: 2017 | K30: 8 | L30: 2 | M30: Propio | N30: Bueno | O30: CRÍTICO | P30: NO | R30: SI | S30: 2023 | T30: INTERNO | U30: TECNICO EQM HPL | X30: 2
A31: UTI - 1B | B31: Hospital Penco Lirquen | C31: Apoyo Terapéutico | D31: Alto Costo | E31: Ventilador mecánico no Invasivo | F31: Covidien | G31: Puritan Bennet 560 | H31: 40966N0851 | I31: HPL30187 | J31: 2020 | K31: 8 | L31: 5 | M31: Préstamo | N31: Bueno | O31: CRÍTICO | P31: NO | R31: SI | S31: 2023 | T31: EXTERNO | V31: LIC 5 | W31: 1039250 | X31: 2
A32: UTI - 1A | B32: Hospital Penco Lirquen | C32: Monitoreo | D32: Alto Costo | E32: Monitor ECG mediana complejidad (pequeño adosado a 03726 ) | F32: Nihon Kohden | G32: BSM-1763K | H32: 8528 | J32: 2023 | K32: 8 | L32: 8 | M32: Préstamo | N32: Bueno | O32: CRÍTICO | P32: NO | R32: SI | S32: 2023 | T32: INTERNO | U32: TECNICO EQM HPL | X32: 2
A33: UTI - 1A | B33: Hospital Penco Lirquen | C33: Monitoreo | D33: Alto Costo | E33: Monitor ECG mediana complejidad (pequeño adosado a 03726 ) | F33: Nihon Kohden | G33: BSM-1763K | H33: 08701 | I33: HPL30135 | J33: 2021 | K33: 8 | L33: 6 | M33: Propio | N33: Bueno | O33: CRÍTICO | P33: NO | R33: SI | S33: 2023 | T33: INTERNO | U33: TECNICO EQM HPL | X33: 2
A34: Bodega equipos médicos - 9C | B34: Hospital Penco Lirquen | C34: Monitoreo | D34: Mediano Costo | E34: Monitor desfibrilador con carro de paro | F34: Schiller | G34: Defigard 4000 | H34: 108994104698 | I34: HPL30092 | J34: 2015 | K34: 8 | L34: 0 | M34: Propio | N34: Bueno | O34: CRÍTICO | P34: NO | R34: SI | S34: 2023 | T34: INTERNO | U34: TECNICO EQM HPL | X34: 2
A35: UTI - 1A | B35: Hospital Penco Lirquen | C35: Monitoreo | D35: Alto Costo | E35: Monitor ECG mediana complejidad (pequeño adosado a 03714) | F35: Nihon Kohden | G35: BSM-1763K | H35: 08699 | I35: HPL30134 | J35: 2021 | K35: 8 | L35: 6 | M35: Propio | N35: Bueno | O35: CRÍTICO | P35: NO | R35: SI | S35: 2023 | T35: INTERNO | U35: TECNICO EQM HPL | X35: 2
A36: UTI - 1A | B36: Hospital Penco Lirquen | C36: Monitoreo | D36: Alto Costo | E36: Monitor ECG mediana complejidad (pequeño adosado a 03717) | F36: Nihon Kohden | G36: BSM-1763K | H36: 08697 | I36: HPL30133 | J36: 2021 | K36: 8 | L36: 6 | M36: Propio | N36: Bueno | O36: CRÍTICO | P36: NO | R36: SI | S36: 2023 | T36: INTERNO | U36: TECNICO EQM HPL | X36: 2
A37: UTI - 1A | B37: Hospital Penco Lirquen | C37: Monitoreo | D37: Alto Costo | E37: Monitor ECG mediana complejidad (pequeño adosado a 03740) | F37: Nihon Kohden | G37: BSM-1763K | H37: 08694 | I37: HPL30132 | J37: 2021 | K37: 8 | L37: 6 | M37: Propio | N37: Bueno | O37: CRÍTICO | P37: NO | R37: SI | S37: 2023 | T37: INTERNO | U37: TECNICO EQM HPL | X37: 2
A38: UTI - 1A | B38: Hospital Penco Lirquen | C38: Monitoreo | D38: Alto Costo | E38: Monitor ECG mediana complejidad | F38: Nihon Kohden | G38: CSM-1502 | H38: 03740 | I38: HPL30129 | J38: 2021 | K38: 8 | L38: 6 | M38: Propio | N38: Bueno | O38: CRÍTICO | P38: NO | R38: SI | S38: 2023 | T38: INTERNO | U38: TECNICO EQM HPL | X38: 2
A39: UTI - 1A | B39: Hospital Penco Lirquen | C39: Monitoreo | D39: Alto Costo | E39: Monitor ECG mediana complejidad | F39: Nihon Kohden | G39: CSM-1502 | H39: 03739 | I39: HPL30128 | J39: 2021 | K39: 8 | L39: 6 | M39: Propio | N39: Bueno | O39: CRÍTICO | P39: NO | R39: SI | S39: 2023 | T39: INTERNO | U39: TECNICO EQM HPL | X39: 2
A40: UTI - 1A | B40: Hospital Penco Lirquen | C40: Monitoreo | D40: Alto Costo | E40: Monitor ECG mediana complejidad | F40: Nihon Kohden | G40: CSM-1502 | H40: 03726 | I40: HPL30127 | J40: 2021 | K40: 8 | L40: 6 | M40: Propio | N40: Bueno | O40: CRÍTICO | P40: NO | R40: SI | S40: 2023 | T40: INTERNO | U40: TECNICO EQM HPL | X40: 2
A41: UTI - 1A | B41: Hospital Penco Lirquen | C41: Monitoreo | D41: Alto Costo | E41: Monitor ECG mediana complejidad | F41: Nihon Kohden | G41: CSM-1502 | H41: 03723 | I41: HPL30126 | J41: 2021 | K41: 8 | L41: 6 | M41: Propio | N41: Bueno | O41: CRÍTICO | P41: NO | R41: SI | S41: 2023 | T41: INTERNO | U41: TECNICO EQM HPL | X41: 2
...

Sheet CATASTRO Y PLANIFICACIÓN MP
A3: SERVICIO DE SALUD | B3: AYSEN
A5: NOMBRE ESTABLECIMIENTO | B5: HOSPITAL DR. LEOPOLDO ORTEGA RODRIGUEZ
A7: RESPONSABLE TÉCNICO | B7: RODRIGO RAMÍREZ PÉREZ | X7: MONITOREO MENSUAL DEL PLAN
X8: % EJECUCIÓN MP TOTAL MENSUAL | Y8: =+'TABLA CÁLCULO'!B24 | Z8: =+'TABLA CÁLCULO'!C24 | AA8: =+'TABLA CÁLCULO'!D24 | AB8: =+'TABLA CÁLCULO'!E24 | AC8: =+'TABLA CÁLCULO'!F24 | AD8: =+'TABLA CÁLCULO'!G24 | AE8: =+'TABLA CÁLCULO'!H24 | AF8: =+'TABLA CÁLCULO'!I24 | ... AJ8: =+'TABLA CÁLCULO'!M24
A9: AÑO DE LEVANTAMIENTO | B9: 2026 | X9: % EJECUCIÓN MP EQC MENSUAL | Y9: =+'TABLA CÁLCULO'!B25 | Z9: =+'TABLA CÁLCULO'!C25 | AA9: =+'TABLA CÁLCULO'!D25 | AB9: =+'TABLA CÁLCULO'!E25 | AC9: =+'TABLA CÁLCULO'!F25 | AD9: =+'TABLA CÁLCULO'!G25 | AE9: =+'TABLA CÁLCULO'!H25 | AF9: =+'TABLA CÁLCULO'!I25 | ... AJ9: =+'TABLA CÁLCULO'!M25
X10: % EJECUCIÓN MP EQR MENSUAL | Y10: =+'TABLA CÁLCULO'!B26 | Z10: =+'TABLA CÁLCULO'!C26 | AA10: =+'TABLA CÁLCULO'!D26 | AB10: =+'TABLA CÁLCULO'!E26 | AC10: =+'TABLA CÁLCULO'!F26 | AD10: =+'TABLA CÁLCULO'!G26 | AE10: =+'TABLA CÁLCULO'!H26 | AF10: =+'TABLA CÁLCULO'!I26 | ... AJ10: =+'TABLA CÁLCULO'!M26
A11: GASTO PROGRAMADO MP | B11: =SUM('SEGUIMIENTO GASTO'!I8:I13) -> 0 | D11: EJECUCIÓN GASTO MP | E11: =+SUM('SEGUIMIENTO GASTO'!AI8:AI13) -> 0 | X11: % EJECUCIÓN MP IM≥12 MENSUAL | Y11: =+'TABLA CÁLCULO'!B27 | Z11: =+'TABLA CÁLCULO'!C27 | AA11: =+'TABLA CÁLCULO'!D27 | AB11: =+'TABLA CÁLCULO'!E27 | AC11: =+'TABLA CÁLCULO'!F27 | AD11: =+'TABLA CÁLCULO'!G27 | AE11: =+'TABLA CÁLCULO'!H27 | AF11: =+'TABLA CÁLCULO'!I27 | ... AJ11: =+'TABLA CÁLCULO'!M27
A13: GASTO PROGRAMADO MC | B13: =SUM('SEGUIMIENTO GASTO'!G21:G26) -> 0 | D13: EJECUCIÓN GASTO MC | E13: =+SUM('SEGUIMIENTO GASTO'!AG21:AG26) -> 0 | Q13: % EJECUCIÓN GASTO MP | T13: % EJECUCIÓN GASTO MC
Y14: CUMPLIMIENTO MANTENIMIENTO PREVENTIVO
A15: SERVICIO CLÍNICO | B15: RECINTO | C15: CLASE | D15: SUBCLASE | E15: NOMBRE EQUIPO | F15: MARCA | G15: MODELO | H15: SERIE | I15: N° INVENTARIO | J15: AÑO DE ADQUISICIÓN | K15: VIDA ÚTIL | L15: VIDA ÚTIL RESIDUAL | M15: PROPIO / ARRIENDO / COMODATO | N15: ESTADO (BUENO / REGULAR / MALO / BAJA) | O15: CRÍTICO/ RELEVANTE / IM≥12 / NO APLICA | P15: EN GARANTÍA (SI / NO) | Q15: AÑO VENCIMIENTO GARANTÍA | R15: BAJO PLAN DE MANTENIMIENTO (SI / NO) | S15: AÑO INGRESO A PLAN DE MANTENIMIENTO (2025 / 2026 / 2027 / 2028) | T15: MANTENIMIENTO INTERNO O MANTENIMIENTO EXTERNO O CONTRATO | U15: NOMBRE DE PROVEEDOR O MANTENIMIENTO INTERNO | V15: ID CONVENIO DE MANTENIMIENTO / ID DE REFERENCIA / COTIZACIÓN DE REFERENCIA | W15: COSTO ANUAL DE MANTENIMIENTO SEGÚN CONVENIO / PRECIO DE REFERENCIA MANTENIMIENTO ANUAL | X15: FRECUENCIA ANUAL DE MANTENIMIENTO | Y15: ENERO | Z15: FEBRERO | AA15: MARZO | AB15: ABRIL | AC15: MAYO | AD15: JUNIO | AE15: JULIO | AF15: AGOSTO | AG15: SEPTIEMBRE | AH15: OCTUBRE | AI15: NOVIEMBRE | AJ15: DICIEMBRE
A16: Laboratorio | B16: Hematología Química Clínica | C16: Laboratorio/Farmacia | D16: Bajo Costo | E16: Agitador de muestras (tipo vortex) | F16: DLAB | G16: MX-S | H16: VB232AS0008474 | I16: 75188 | J16: 2025 | K16: 10 | L16: =K16-($B$9-J16) -> 9 | M16: PROPIO | N16: BUENO | O16: RELEVANTE | P16: SI | Q16: 2026 | R16: SI | S16: 2026 | T16: Mantenimiento Externo | U16: Arquimed | X16: 1 | AD16: X
A17: Laboratorio | B17: Bacteriología y Orina | C17: Laboratorio/Farmacia | D17: Bajo Costo | E17: Agitador Magnetico (RPR) | F17: DIGISYSTEM | G17: DS-DSR2100D | H17: S/S | I17: 75067 | J17: 2025 | K17: 10 | L17: =K17-($B$9-J17) -> 9 | M17: PROPIO | N17: BUENO | O17: RELEVANTE | P17: NO | Q17: 2025 | R17: SI | S17: 2026 | T17: Mantenimiento Externo | U17: Farmalatina | X17: 1 | AA17: ꓣ
A18: Laboratorio | B18: Hematología Química Clínica | C18: Laboratorio/Farmacia | D18: Alto Costo | E18: Analizador Hematologico Digital (Células Sanguíneas) | F18: DIGISYSTEM | G18: DBC-9D-M | H18: S/S | I18: 75066 | J18: 2025 | K18: 10 | L18: =K18-($B$9-J18) -> 9 | M18: PROPIO | N18: BUENO | O18: RELEVANTE | P18: NO | Q18: 2025 | R18: SI | S18: 2026 | T18: Mantenimiento Externo | U18: Farmalatina | X18: 1 | AA18: ꓣ
A19: Atención Abierta | B19: Laboratorio Dental | C19: Odontología | D19: Bajo Costo | E19: Arenadora con cajón | F19: ESSENCE | G19: EVOLUT | H19: TJ0124 | I19: 76577 | J19: 2025 | K19: 10 | L19: =K19-($B$9-J19) -> 9 | M19: PROPIO | N19: BUENO | O19: NO APLICA | P19: SI | Q19: 2026 | R19: SI | S19: 2027 | T19: Mantenimiento Interno | U19: Dental Laval | X19: 1 | AD19: X
A20: Hospital Antiguo | B20: Bodega EQM | C20: Esterilización | D20: Alto Costo | E20: AUTOCLAVE | F20: MINGTAI | G20: SUN45-III | H20: SA2211296 | I20: 74052 | J20: 2015 | K20: 10 | L20: 0 | M20: PROPIO | N20: BUENO | O20: RELEVANTE | P20: NO | Q20: NO APLICA | R20: SI | S20: 2025 | T20: Mantenimiento Externo | U20: ITALO BRAVO | W20: 816550 | X20: 1 | AC20: X
A21: Esterilización | B21: Material Esteril (Autoclave) | C21: Esterilización | D21: Alto Costo | E21: Autoclave 100 Litros (2 STU) | F21: MATACHANA | G21: SC500E-1 | H21: E-35162 | I21: 75041 | J21: 2025 | K21: 10 | L21: =K21-($B$9-J21) -> 9 | M21: PROPIO | N21: BUENO | O21: RELEVANTE | P21: SI | Q21: 2026 | R21: SI | S21: 2025 | T21: Mantenimiento Externo | U21: IClinics | X21: 2 | AC21: X | AI21: X
A22: Sedile | B22: Sedile | C22: Esterilización | D22: Alto Costo | E22: Autoclave 21 Litros | F22: MATACHANA | G22: M20-B | H22: 34122 | I22: 75039 | J22: 2025 | K22: 10 | L22: =K22-($B$9-J22) -> 9 | M22: PROPIO | N22: BUENO | O22: RELEVANTE | P22: SI | Q22: 2026 | R22: SI | S22: 2025 | T22: Mantenimiento Externo | U22: IClinics | X22: 2 | AC22: X | AI22: X
A23: Laboratorio | B23: Descontaminacion y Lavado | C23: Esterilización | D23: Alto Costo | E23: Autoclave 50Lt vertical | F23: RAYPA | G23: AE-50-DRY | H23: 443333 | I23: 75038 | J23: 2025 | K23: 10 | L23: =K23-($B$9-J23) -> 9 | M23: PROPIO | N23: BUENO | O23: RELEVANTE | P23: SI | Q23: 2026 | R23: SI | S23: 2025 | T23: Mantenimiento Externo | U23: IClinics | X23: 2 | AC23: X | AI23: X
A24: Unidad Urgencias | B24: Closet EQM | C24: Apoyo Diagnóstico | D24: Alto Costo | E24: Autorefractómetro | F24: NIDEK | G24: Ark-1 | H24: S/N | I24: 75071 | J24: 2025 | K24: 10 | L24: =K24-($B$9-J24) -> 9 | M24: PROPIO | N24: BUENO | O24: IM ≥ 12 | P24: SI | Q24: 2027 | R24: SI | S24: 2026 | T24: Mantenimiento Externo | U24: Alta Tecnologia Medica | X24: 1 | AD24: X
A25: Laboratorio | B25: Entrega de Sangre (Unidad Medicina Transfusional) | C25: Laboratorio/Farmacia | D25: Mediano Costo | E25: Balanza de presición | F25: BIOLOGIX | G25: 01-BD304N4 | H25: YS05202410006 | I25: 75302 | J25: 2025 | K25: 10 | L25: =K25-($B$9-J25) -> 9 | M25: PROPIO | N25: BUENO | O25: RELEVANTE | P25: NO | Q25: 2025 | R25: SI | S25: 2026 | T25: Mantenimiento Externo | U25: Microx Chile | X25: 1 | AA25: ꓣ | AD25: X
A26: Laboratorio | B26: Hematología Química Clínica | C26: Laboratorio/Farmacia | D26: Bajo Costo | E26: Baño Termoregulado | F26: LAUDA | G26: HYDRO H8 | H26: S230014557 | I26: 75187 | J26: 2025 | K26: 10 | L26: =K26-($B$9-J26) -> 9 | M26: PROPIO | N26: BUENO | O26: RELEVANTE | P26: SI | Q26: 2026 | R26: SI | S26: 2027 | T26: Mantenimiento Externo | U26: Arquimed | X26: 1 | AD26: X
A27: Hospital Antiguo | B27: Bodega EQM | C27: Med. Física y Rehabilitación | D27: Alto Costo | E27: BAÑO TURBIÓN EXTREMIDAD INFERIOR | F27: S/M | G27: S/M | H27: S/N | I27: 74177 | J27: 2015 | K27: 10 | L27: 0 | M27: PROPIO | N27: BUENO | O27: IM ≥ 12 | P27: NO | Q27: NO APLICA | R27: SI | S27: 2026 | T27: Mantenimiento Interno | X27: 1 | AJ27: X
A28: Medicina Fisica y Rehabilitación | B28: Area de Gimnasio infantil y adulto (actividades terapeuticas) | C28: Med. Física y Rehabilitación | D28: Mediano Costo | E28: Bicicleta Ergonométrica | F28: DYACO | G28: 7.0 | H28: 20-24080029 | I28: 75299 | J28: 2025 | K28: 10 | L28: =K28-($B$9-J28) -> 9 | M28: PROPIO | N28: BUENO | O28: IM ≥ 12 | P28: SI | Q28: 2027 | R28: SI | S28: 2026 | T28: Mantenimiento Externo | U28: Quimicolor | X28: 1 | AC28: X
A29: Medicina Fisica y Rehabilitación | B29: Area de Gimnasio infantil y adulto (actividades terapeuticas) | C29: Med. Física y Rehabilitación | D29: Mediano Costo | E29: Bicicleta Ergonométrica | F29: DYACO | G29: 7.0 | H29: 30-24080019 | I29: 75300 | J29: 2025 | K29: 10 | L29: =K29-($B$9-J29) -> 9 | M29: PROPIO | N29: BUENO | O29: IM ≥ 12 | P29: SI | Q29: 2027 | R29: SI | S29: 2026 | T29: Mantenimiento Externo | U29: Quimicolor | X29: 1 | AC29: X
A30: Atención Cerrada Hospitalización | B30: Bodega de Equipos | C30: Apoyo Terapéutico | D30: Bajo Costo | E30: Bomba Alimentación Enteral | F30: FEEGIND PUMP | G30: FP300 | H30: 8014223 | I30: 75134 | J30: 2025 | K30: 10 | L30: =K30-($B$9-J30) -> 9 | M30: PROPIO | N30: BUENO | O30: NO APLICA | P30: SI | Q30: 2026 | R30: SI | S30: 2026 | T30: Mantenimiento Externo | U30: Skill Training | X30: 2 | AA30: ꓣ | AB30: X | AH30: X
A31: Unidad Urgencia Pabellón Quirúrgico | B31: Pabellón Quirúrgico Multiproposito | C31: Apoyo Quirúrgico | D31: Bajo Costo | E31: Bomba Aspiración Quirúrgica | F31: CAMI | G31: NEW HOSPIVAC 350 | H31: 41017 | I31: 75072 | J31: 2025 | K31: 10 | L31: =K31-($B$9-J31) -> 9 | M31: PROPIO | N31: BUENO | O31: IM ≥ 12 | P31: SI | Q31: 2026 | R31: SI | S31: 2026 | T31: Mantenimiento Externo | U31: Bioscom | X31: 1 | AH31: X
A32: Unidad Urgencia Pabellón Quirúrgico | B32: Sala de Parto Integral | C32: Apoyo Quirúrgico | D32: Bajo Costo | E32: Bomba Aspiración Quirúrgica | F32: CAMI | G32: NEW HOSPIVAC 350 | H32: 41013 | I32: 75073 | J32: 2025 | K32: 10 | L32: =(J32+K32)-$B$9 -> 9 | M32: PROPIO | N32: BUENO | O32: IM ≥ 12 | P32: SI | Q32: 2026 | R32: SI | S32: 2026 | T32: Mantenimiento Externo | U32: Bioscom | X32: 1 | AH32: X
A33: Hospital Antiguo | B33: Bodega EQM | C33: Apoyo Quirúrgico | D33: Bajo Costo | E33: Bomba de Aspiración | F33: CA-MI | G33: 230-12BR | H33: 2470 | I33: 74184 | J33: 2015 | K33: 10 | L33: 0 | M33: PROPIO | N33: BUENO | O33: IM ≥ 12 | P33: NO | Q33: NO APLICA | R33: SI | S33: 2025 | T33: Mantenimiento Externo | U33: MEDICAL SYSTEM | W33: 246971.63 | X33: 1 | AJ33: X
A34: Hospital Antiguo | B34: Bodega EQM | C34: Apoyo Quirúrgico | D34: Bajo Costo | E34: Bomba de Aspiración | F34: DEVILBISS | G34: 7314P-D | H34: 4PD061810 | I34: 74191 | J34: 2015 | K34: 10 | L34: 0 | M34: PROPIO | N34: BUENO | O34: IM ≥ 12 | P34: NO | Q34: NO APLICA | R34: SI | S34: 2025 | T34: Mantenimiento Externo | U34: MEDICAL SYSTEM | W34: 246971.63 | X34: 1 | AJ34: X
A35: Hospital Antiguo | B35: Bodega EQM | C35: Apoyo Quirúrgico | D35: Bajo Costo | E35: Bomba de Aspiración | F35: EACHMAN | G35: VP35 | H35: V3AB-90-1141 | I35: 74210 | J35: 2015 | K35: 10 | L35: 0 | M35: PROPIO | N35: BUENO | O35: IM ≥ 12 | P35: NO | Q35: NO APLICA | R35: SI | S35: 2025 | T35: Mantenimiento Externo | U35: MEDICAL SYSTEM | W35: 246971.63 | X35: 1 | AJ35: X
A36: Hospital Antiguo | B36: Bodega EQM | C36: Apoyo Quirúrgico | D36: Bajo Costo | E36: Bomba de Aspiración | F36: MEDI AIR | G36: SUBOI SERIES | H36: SU12K00846 | I36: 74194 | J36: 2015 | K36: 10 | L36: 0 | M36: PROPIO | N36: BUENO | O36: IM ≥ 12 | P36: NO | Q36: NO APLICA | R36: SI | S36: 2025 | T36: Mantenimiento Externo | U36: MEDICAL SYSTEM | W36: 246971.63 | X36: 1 | AJ36: X
A37: Hospital Antiguo | B37: Bodega EQM | C37: Apoyo Quirúrgico | D37: Bajo Costo | E37: Bomba de Aspiración | F37: NEW ASKIR | G37: 230-12BR | H37: 19979 | I37: 74187 | J37: 2015 | K37: 10 | L37: 0 | M37: PROPIO | N37: BUENO | O37: IM ≥ 12 | P37: NO | Q37: NO APLICA | R37: SI | S37: 2025 | T37: Mantenimiento Externo | U37: MEDICAL SYSTEM | W37: 246971.63 | X37: 1 | AJ37: X
A38: Hospital Antiguo | B38: Bodega EQM | C38: Apoyo Quirúrgico | D38: Bajo Costo | E38: Bomba de Aspiración | F38: THOMAS | G38: 1636 | H38: 16900002248 | J38: 2015 | K38: 10 | L38: 0 | M38: PROPIO | N38: BUENO | O38: IM ≥ 12 | P38: NO | Q38: NO APLICA | R38: SI | S38: 2025 | T38: Mantenimiento Externo | U38: MEDICAL SYSTEM | W38: 246971.63 | X38: 1 | AJ38: X
A39: Hospital Antiguo | B39: Bodega EQM | C39: Apoyo Quirúrgico | D39: Bajo Costo | E39: Bomba de Aspiración | F39: APEX MEDICAL | G39: VAC PLUS | H39: 077B-04591 | J39: 2024 | K39: 10 | L39: 9 | M39: PROPIO | N39: REGULAR | O39: IM ≥ 12 | P39: NO | Q39: NO APLICA | R39: NO | T39: Mantenimiento Externo | X39: 1 | AJ39: X
A40: Atención Cerrada Hospitalización | B40: Bodega de Equipos | C40: Apoyo Quirúrgico | D40: Bajo Costo | E40: Bomba de Aspiración | F40: FLAEM | G40: ASPIRA PLUS | H40: 23AK260037 | I40: 76591 | J40: 2025 | K40: 10 | L40: =(J40+K40)-$B$9 -> 9 | M40: PROPIO | N40: BUENO | O40: IM ≥ 12 | P40: SI | Q40: 2026 | R40: SI | S40: 2025 | T40: Mantenimiento Externo | U40: Mediplex | X40: 1 | AD40: X
A41: Atención Abierta | B41: Box Tratamiento Respiratorio (IRA) | C41: Apoyo Quirúrgico | D41: Bajo Costo | E41: Bomba de Aspiración | F41: FLAEM | G41: ASPIRA PLUS | H41: 23AK260048 | I41: 75108 | J41: 2025 | K41: 10 | L41: =K41-($B$9-J41) -> 9 | M41: PROPIO | N41: BUENO | O41: IM ≥ 12 | P41: SI | Q41: 2026 | R41: SI | S41: 2025 | T41: Mantenimiento Externo | U41: Mediplex | X41: 1 | AD41: X
A42: Atención Cerrada Hospitalización | B42: Estación Enfermería | C42: Apoyo Quirúrgico | D42: Bajo Costo | E42: Bomba de Aspiración | F42: FLAEM | G42: ASPIRA PLUS | H42: 23AK260047 | I42: 75110 | J42: 2025 | K42: 10 | L42: =K42-($B$9-J42) -> 9 | M42: PROPIO | N42: BUENO | O42: IM ≥ 12 | P42: SI | Q42: 2026 | R42: SI | S42: 2025 | T42: Mantenimiento Externo | U42: Mediplex | X42: 1 | AD42: X
A43: Unidad Urgencias | B43: Estación Enfermería | C43: Apoyo Quirúrgico | D43: Bajo Costo | E43: Bomba de Aspiración | F43: FLAEM | G43: ASPIRA PLUS | H43: 23AK260031 | I43: 75113 | J43: 2025 | K43: 10 | L43: =K43-($B$9-J43) -> 9 | M43: PROPIO | N43: BUENO | O43: IM ≥ 12 | P43: SI | Q43: 2026 | R43: SI | S43: 2025 | T43: Mantenimiento Externo | U43: Mediplex | X43: 1 | AD43: X
A44: Unidad Urgencias | B44: Sala Reanimación | C44: Apoyo Quirúrgico | D44: Bajo Costo | E44: Bomba de Aspiración | F44: FLAEM | G44: ASPIRA PLUS | H44: 23AK260032 | I44: 75114 | J44: 2025 | K44: 10 | L44: =K44-($B$9-J44) -> 9 | M44: PROPIO | N44: BUENO | O44: IM ≥ 12 | P44: SI | Q44: 2026 | R44: SI | S44: 2025 | T44: Mantenimiento Externo | U44: Mediplex | X44: 1 | AD44: X
A45: Unidad Urgencias | B45: Box Atención 2 | C45: Apoyo Quirúrgico | D45: Bajo Costo | E45: Bomba de Aspiración | F45: FLAEM | G45: ASPIRA PLUS | H45: 23AK260038 | I45: 75115 | J45: 2025 | K45: 10 | L45: =K45-($B$9-J45) -> 9 | M45: PROPIO | N45: BUENO | O45: IM ≥ 12 | P45: SI | Q45: 2026 | R45: SI | S45: 2025 | T45: Mantenimiento Externo | U45: Mediplex | X45: 1 | AD45: X
...

Sheet Hoja3
A1: SERVICIO CLÍNICO | B1: RECINTO | C1: CLASE | D1: SUBCLASE | E1: NOMBRE EQUIPO | F1: MARCA | G1: MODELO | H1: SERIE | I1: N° INVENTARIO
A2: Laboratorio | B2: Hematología Química Clínica | C2: Laboratorio/Farmacia | D2: Bajo Costo | E2: Agitador de muestras (tipo vortex) | F2: DLAB | G2: MX-S | H2: VB232AS0008474 | I2: 75188
A3: Laboratorio | B3: Bacteriología y Orina | C3: Laboratorio/Farmacia | D3: Bajo Costo | E3: Agitador Magnetico (RPR) | F3: DIGISYSTEM | G3: DS-DSR2100D | H3: S/S | I3: 75067
A4: Laboratorio | B4: Hematología Química Clínica | C4: Laboratorio/Farmacia | D4: Alto Costo | E4: Analizador Hematologico Digital (Células Sanguíneas) | F4: DIGISYSTEM | G4: DBC-9D-M | H4: S/S | I4: 75066
A5: Atención Abierta | B5: Laboratorio Dental | C5: Odontología | D5: Bajo Costo | E5: Arenadora con cajón | F5: ESSENCE | G5: EVOLUT | H5: TJ0124 | I5: 76577
A6: Hospital Antiguo | B6: Bodega EQM | C6: Esterilización | D6: Alto Costo | E6: AUTOCLAVE | F6: MINGTAI | G6: SUN45-III | H6: SA2211296 | I6: 74052
A7: Esterilización | B7: Material Esteril (Autoclave) | C7: Esterilización | D7: Alto Costo | E7: Autoclave 100 Litros (2 STU) | F7: MATACHANA | G7: SC500E-1 | H7: E-35162 | I7: 75041
A8: Sedile | B8: Sedile | C8: Esterilización | D8: Alto Costo | E8: Autoclave 21 Litros | F8: MATACHANA | G8: M20-B | H8: 34122 | I8: 75039
A9: Laboratorio | B9: Descontaminacion y Lavado | C9: Esterilización | D9: Alto Costo | E9: Autoclave 50Lt vertical | F9: RAYPA | G9: AE-50-DRY | H9: 443333 | I9: 75038
A10: Unidad Urgencias | B10: Closet EQM | C10: Apoyo Diagnóstico | D10: Alto Costo | E10: Autorefractómetro | F10: NIDEK | G10: Ark-1 | H10: S/N | I10: 75071
A11: Laboratorio | B11: Entrega de Sangre (Unidad Medicina Transfusional) | C11: Laboratorio/Farmacia | D11: Mediano Costo | E11: Balanza de presición | F11: BIOLOGIX | G11: 01-BD304N4 | H11: YS05202410006 | I11: 75302
A12: Laboratorio | B12: Hematología Química Clínica | C12: Laboratorio/Farmacia | D12: Bajo Costo | E12: Baño Termoregulado | F12: LAUDA | G12: HYDRO H8 | H12: S230014557 | I12: 75187
A13: Hospital Antiguo | B13: Bodega EQM | C13: Med. Física y Rehabilitación | D13: Alto Costo | E13: BAÑO TURBIÓN EXTREMIDAD INFERIOR | F13: S/M | G13: S/M | H13: S/N | I13: 74177
A14: Medicina Fisica y Rehabilitación | B14: Area de Gimnasio infantil y adulto (actividades terapeuticas) | C14: Med. Física y Rehabilitación | D14: Mediano Costo | E14: Bicicleta Ergonométrica | F14: DYACO | G14: 7.0 | H14: 20-24080029 | I14: 75299
A15: Medicina Fisica y Rehabilitación | B15: Area de Gimnasio infantil y adulto (actividades terapeuticas) | C15: Med. Física y Rehabilitación | D15: Mediano Costo | E15: Bicicleta Ergonométrica | F15: DYACO | G15: 7.0 | H15: 30-24080019 | I15: 75300
A16: Atención Cerrada Hospitalización | B16: Bodega de Equipos | C16: Apoyo Terapéutico | D16: Bajo Costo | E16: Bomba Alimentación Enteral | F16: FEEGIND PUMP | G16: FP300 | H16: 8014223 | I16: 75134
A17: Unidad Urgencia Pabellón Quirúrgico | B17: Pabellón Quirúrgico Multiproposito | C17: Apoyo Quirúrgico | D17: Bajo Costo | E17: Bomba Aspiración Quirúrgica | F17: CAMI | G17: NEW HOSPIVAC 350 | H17: 41017 | I17: 75072
A18: Unidad Urgencia Pabellón Quirúrgico | B18: Sala de Parto Integral | C18: Apoyo Quirúrgico | D18: Bajo Costo | E18: Bomba Aspiración Quirúrgica | F18: CAMI | G18: NEW HOSPIVAC 350 | H18: 41013 | I18: 75073
A19: Hospital Antiguo | B19: Bodega EQM | C19: Apoyo Quirúrgico | D19: Bajo Costo | E19: Bomba de Aspiración | F19: CA-MI | G19: 230-12BR | H19: 2470 | I19: 74184
A20: Hospital Antiguo | B20: Bodega EQM | C20: Apoyo Quirúrgico | D20: Bajo Costo | E20: Bomba de Aspiración | F20: DEVILBISS | G20: 7314P-D | H20: 4PD061810 | I20: 74191
A21: Hospital Antiguo | B21: Bodega EQM | C21: Apoyo Quirúrgico | D21: Bajo Costo | E21: Bomba de Aspiración | F21: EACHMAN | G21: VP35 | H21: V3AB-90-1141 | I21: 74210
A22: Hospital Antiguo | B22: Bodega EQM | C22: Apoyo Quirúrgico | D22: Bajo Costo | E22: Bomba de Aspiración | F22: MEDI AIR | G22: SUBOI SERIES | H22: SU12K00846 | I22: 74194
A23: Hospital Antiguo | B23: Bodega EQM | C23: Apoyo Quirúrgico | D23: Bajo Costo | E23: Bomba de Aspiración | F23: NEW ASKIR | G23: 230-12BR | H23: 19979 | I23: 74187
A24: Hospital Antiguo | B24: Bodega EQM | C24: Apoyo Quirúrgico | D24: Bajo Costo | E24: Bomba de Aspiración | F24: THOMAS | G24: 1636 | H24: 16900002248
A25: Hospital Antiguo | B25: Bodega EQM | C25: Apoyo Quirúrgico | D25: Bajo Costo | E25: Bomba de Aspiración | F25: APEX MEDICAL | G25: VAC PLUS | H25: 077B-04591
A26: Atención Cerrada Hospitalización | B26: Bodega de Equipos | C26: Apoyo Quirúrgico | D26: Bajo Costo | E26: Bomba de Aspiración | F26: FLAEM | G26: ASPIRA PLUS | H26: 23AK260037 | I26: 76591
A27: Atención Abierta | B27: Box Tratamiento Respiratorio (IRA) | C27: Apoyo Quirúrgico | D27: Bajo Costo | E27: Bomba de Aspiración | F27: FLAEM | G27: ASPIRA PLUS | H27: 23AK260048 | I27: 75108
A28: Atención Cerrada Hospitalización | B28: Estación Enfermería | C28: Apoyo Quirúrgico | D28: Bajo Costo | E28: Bomba de Aspiración | F28: FLAEM | G28: ASPIRA PLUS | H28: 23AK260047 | I28: 75110
A29: Unidad Urgencias | B29: Estación Enfermería | C29: Apoyo Quirúrgico | D29: Bajo Costo | E29: Bomba de Aspiración | F29: FLAEM | G29: ASPIRA PLUS | H29: 23AK260031 | I29: 75113
A30: Unidad Urgencias | B30: Sala Reanimación | C30: Apoyo Quirúrgico | D30: Bajo Costo | E30: Bomba de Aspiración | F30: FLAEM | G30: ASPIRA PLUS | H30: 23AK260032 | I30: 75114
A31: Unidad Urgencias | B31: Box Atención 2 | C31: Apoyo Quirúrgico | D31: Bajo Costo | E31: Bomba de Aspiración | F31: FLAEM | G31: ASPIRA PLUS | H31: 23AK260038 | I31: 75115
A32: Unidad Urgencia Pabellón Quirúrgico | B32: Estación Enfermería (Área Limpia) | C32: Apoyo Terapéutico | D32: Mediano Costo | E32: Bomba Infusión Jeringa | F32: BRAUN | G32: B/BRAUN | H32: 644181 | I32: 75275
A33: Hospital Antiguo | B33: Bodega EQM | C33: Apoyo Terapéutico | D33: Mediano Costo | E33: Bomba Infusión Volumétrica | F33: BBRAUN | G33: INFUSOMAT COMPACT | H33: 46195 | I33: 74061
A34: Hospital Antiguo | B34: Bodega EQM | C34: Apoyo Terapéutico | D34: Mediano Costo | E34: Bomba Infusión Volumétrica | F34: FRESENIUS KABI | G34: VOLUMAT MAC AGILIA | H34: 019181/22324963 | I34: 74062
A35: Hospital Antiguo | B35: Bodega EQM | C35: Apoyo Terapéutico | D35: Mediano Costo | E35: Bomba Infusión Volumétrica | F35: FRESENIUS KABI | G35: VOLUMAT MAC AGILIA | H35: 20885416 | I35: 74201
A36: Hospital Antiguo | B36: Bodega EQM | C36: Apoyo Terapéutico | D36: Mediano Costo | E36: Bomba Infusión Volumétrica | F36: BBRAUN | G36: SPACE PLUS INFUSOMAT | H36: 51822 | I36: 74197
A37: Atención Cerrada Hospitalización | B37: Bodega de Equipos | C37: Apoyo Terapéutico | D37: Mediano Costo | E37: Bomba Infusión Volumétrica | F37: BRAUN | G37: INFUSOMAT | H37: 976105 | I37: 75263
A38: Unidad Urgencia Pabellón Quirúrgico | B38: Pabellón Quirúrgico Multiproposito | C38: Apoyo Terapéutico | D38: Mediano Costo | E38: Bomba Infusión Volumétrica | F38: BRAUN | G38: INFUSOMAT | H38: 976085 | I38: 75264
A39: Atención Cerrada Hospitalización | B39: Bodega de Equipos | C39: Apoyo Terapéutico | D39: Mediano Costo | E39: Bomba Infusión Volumétrica | F39: BRAUN | G39: INFUSOMAT | H39: 976184 | I39: 75265
A40: Atención Cerrada Hospitalización | B40: Bodega de Equipos | C40: Apoyo Terapéutico | D40: Mediano Costo | E40: Bomba Infusión Volumétrica | F40: BRAUN | G40: INFUSOMAT | H40: 976084 | I40: 75266
...

Sheet SEGUIMIENTO GASTO
B3: SEGUIMIENTO GASTO CONVENIOS DE MANTENIMIENTO
K5: CONTROL MENSUAL EJECUCIÓN
K6: ENERO | M6: FEBRERO | O6: MARZO | Q6: ABRIL | S6: MAYO | U6: JUNIO | W6: JULIO | Y6: AGOSTO | AA6: SEPTIEMBRE | AC6: OCTUBRE | AE6: NOVIEMBRE | AG6: DICIEMBRE
B7: Nº | C7: SERVICIO DE SALUD | D7: ESTABLECIMIENTO | E7: NOMBRE CONVENIO DE MANTENIMIENTO | F7: Nº RESOLUCIÓN / ID / ORDEN DE COMPRA DEL CONVENIO | G7: FECHA RESOLUCIÓN | H7: FECHA DE EXPIRACION CONVENIO | I7: MONTO ANUAL ($) | J7: SUBASIGNACIÓN SIGFE | K7: N° ORDEN DE COMPRA / N° FACTURA | L7: MONTO ($) | M7: N° ORDEN DE COMPRA / N° FACTURA | N7: MONTO ($) | O7: N° ORDEN DE COMPRA / N° FACTURA | P7: MONTO ($) | Q7: N° ORDEN DE COMPRA / N° FACTURA | R7: MONTO ($) | S7: N° ORDEN DE COMPRA / N° FACTURA | T7: MONTO ($) | U7: N° ORDEN DE COMPRA / N° FACTURA | V7: MONTO ($) | W7: N° ORDEN DE COMPRA / N° FACTURA | X7: MONTO ($) | Y7: N° ORDEN DE COMPRA / N° FACTURA | Z7: MONTO ($) | AA7: N° ORDEN DE COMPRA / N° FACTURA | AB7: MONTO ($) | AC7: N° ORDEN DE COMPRA / N° FACTURA | AD7: MONTO ($) | AE7: N° ORDEN DE COMPRA / N° FACTURA | AF7: MONTO ($) | AG7: N° ORDEN DE COMPRA / N° FACTURA | AH7: MONTO ($) | AI7: TOTAL
AI8: =L8+N8+P8+R8+T8+V8+X8+Z8+AB8+AD8+AF8+AH8 -> 0
AI9: =L9+N9+P9+R9+T9+V9+X9+Z9+AB9+AD9+AF9+AH9 -> 0
AI10: =L10+N10+P10+R10+T10+V10+X10+Z10+AB10+AD10+AF10+AH10 -> 0
AI11: =L11+N11+P11+R11+T11+V11+X11+Z11+AB11+AD11+AF11+AH11 -> 0
AI12: =L12+N12+P12+R12+T12+V12+X12+Z12+AB12+AD12+AF12+AH12 -> 0
AI13: =L13+N13+P13+R13+T13+V13+X13+Z13+AB13+AD13+AF13+AH13 -> 0
I14: =SUM(I8:I13) -> 0
B16: SEGUIMIENTO GASTO MANTENIMIENTO CORRECTIVO / ADQUISICIÓN DE REPUESTOS / ADQUISICIÓN DE INSUMOS / ADQUISICIÓN DE ACCESORIOS
I18: CONTROL MENSUAL EJECUCIÓN
I19: ENERO | K19: FEBRERO | M19: MARZO | O19: ABRIL | Q19: MAYO | S19: JUNIO | U19: JULIO | W19: AGOSTO | Y19: SEPTIEMBRE | AA19: OCTUBRE | AC19: NOVIEMBRE | AE19: DICIEMBRE
B20: Nº | C20: SERVICIO DE SALUD | D20: ESTABLECIMIENTO | E20: DESCRIPCIÓN DE LA COMPRA | F20: TIPO DE GASTO CORRECTIVO | G20: MONTO | H20: SUBASIGNACIÓN SIGFE | I20: N° ORDEN DE COMPRA | J20: MONTO ($) | K20: N° ORDEN DE COMPRA | L20: MONTO ($) | M20: N° ORDEN DE COMPRA | N20: MONTO ($) | O20: N° ORDEN DE COMPRA | P20: MONTO ($) | Q20: N° ORDEN DE COMPRA | R20: MONTO ($) | S20: N° ORDEN DE COMPRA | T20: MONTO ($) | U20: N° ORDEN DE COMPRA | V20: MONTO ($) | W20: N° ORDEN DE COMPRA | X20: MONTO ($) | Y20: N° ORDEN DE COMPRA | Z20: MONTO ($) | AA20: N° ORDEN DE COMPRA | AB20: MONTO ($) | AC20: N° ORDEN DE COMPRA | AD20: MONTO ($) | AE20: N° ORDEN DE COMPRA | AF20: MONTO ($) | AG20: TOTAL
AG21: =+J21+L21+N21+P21+R21+T21+V21+X21+Z21+AB21+AD21+AF21 -> 0
AG22: =+J22+L22+N22+P22+R22+T22+V22+X22+Z22+AB22+AD22+AF22 -> 0
AG23: =+J23+L23+N23+P23+R23+T23+V23+X23+Z23+AB23+AD23+AF23 -> 0
AG24: =+J24+L24+N24+P24+R24+T24+V24+X24+Z24+AB24+AD24+AF24 -> 0
AG25: =+J25+L25+N25+P25+R25+T25+V25+X25+Z25+AB25+AD25+AF25 -> 0
AG26: =+J26+L26+N26+P26+R26+T26+V26+X26+Z26+AB26+AD26+AF26 -> 0

Sheet Detalle2
A1: Detalles para Suma de FRECUENCIA ANUAL DE MANTENIMIENTO - CRÍTICO/ RELEVANTE / IM≥12 / NO APLICA: CRÍTICO
A3: SERVICIO CLÍNICO | B3: RECINTO | C3: CLASE | D3: SUBCLASE | E3: NOMBRE EQUIPO | F3: MARCA | G3: MODELO | H3: SERIE | I3: N° INVENTARIO | J3: AÑO DE ADQUISICIÓN | K3: VIDA ÚTIL | L3: VIDA ÚTIL RESIDUAL | M3: PROPIO / ARRIENDO / COMODATO | N3: ESTADO (BUENO / REGULAR / MALO / BAJA) | O3: CRÍTICO/ RELEVANTE / IM≥12 / NO APLICA | P3: EN GARANTÍA (SI / NO) | Q3: AÑO VENCIMIENTO GARANTÍA | R3: BAJO PLAN DE MANTENIMIENTO (SI / NO) | S3: AÑO INGRESO A PLAN DE MANTENIMIENTO (2023 / 2024 / 2025 / 2026) | T3: MANTENIMIENTO INTERNO O MANTENIMIENTO EXTERNO O CONTRATO | U3: NOMBRE DE PROVEEDOR O MANTENIMIENTO INTERNO | V3: ID CONVENIO DE MANTENIMIENTO / ID DE REFERENCIA / COTIZACIÓN DE REFERENCIA | W3: COSTO ANUAL DE MANTENIMIENTO SEGÚN CONVENIO / PRECIO DE REFERENCIA MANTENIMIENTO ANUAL | X3: FRECUENCIA ANUAL DE MANTENIMIENTO | Y3: ENERO | Z3: FEBRERO | AA3: MARZO | AB3: ABRIL | AC3: MAYO | AD3: JUNIO | AE3: JULIO | AF3: AGOSTO | AG3: SEPTIEMBRE | AH3: OCTUBRE | AI3: NOVIEMBRE | AJ3: DICIEMBRE
A4: Pabellón | B4: Hospital Penco Lirquen | C4: Monitoreo | D4: Mediano Costo | E4: Monitor ECG Baja Complejidad | F4: Philips | G4: Efficia CM100 | H4: CN12099172 | J4: 2023 | K4: 8 | L4: 7 | M4: Propio | N4: Bueno | O4: CRÍTICO | P4: SI | Q4: 45627 | R4: SI | S4: 2024 | T4: EXTERNO | U4: Andover | V4: COLDAS | X4: 1 | AJ4: X
A5: Especialidades cuidados paliativos | B5: Hospital Penco Lirquen | C5: Apoyo Terapéutico | E5: Monitor Signos Vitales | F5: Nothern Meditec Limited | G5: Aquarius | H5: JHC01B508004 | J5: 2024 | K5: 8 | L5: 8 | M5: Propio | N5: Bueno | O5: CRÍTICO | P5: SI | Q5: 46174 | R5: SI | S5: 2024 | T5: EXTERNO | U5: BALDER | V5: 1057931-4-LE24 | X5: 1 | AI5: X
A6: Ambulancia - 7B | B6: Hospital Penco Lirquen | C6: Monitoreo | D6: Mediano Costo | E6: Monitor ECG Baja Complejidad | F6: Nihon Kohden | G6: SVM-7260 | H6: 00292 | I6: HPL30123 | J6: 2020 | K6: 8 | L6: 4 | M6: Propio | N6: Bueno | O6: CRÍTICO | P6: NO | Q6: NO APLICA | R6: SI | S6: 2023 | T6: INTERNO | U6: TECNICO EQM HPL | V6: NO APLICA | X6: 2 | AC6: √ | AI6: X
A7: Ambulancia - 7B | B7: Hospital Penco Lirquen | C7: Monitoreo | D7: Mediano Costo | E7: Monitor ECG Baja Complejidad | F7: Mindray | G7: uMEC10 | H7: KN-03065493 | I7: HPL30261 | J7: 2020 | K7: 8 | L7: 4 | M7: Propio | N7: Bueno | O7: CRÍTICO | P7: NO | Q7: NO APLICA | R7: SI | S7: 2023 | T7: INTERNO | U7: TECNICO EQM HPL | V7: NO APLICA | X7: 2 | AC7: ꓣ | AD7: √ | AI7: X
A8: UTI - 9D | B8: Hospital Penco Lirquen | C8: Apoyo Terapéutico | D8: Alto Costo | E8: Ventilador mecánico no Invasivo | F8: Philips | G8: Trilogy 202 | H8: TV016091214 | I8: HPL24776 | J8: 2016 | K8: 8 | L8: 0 | M8: Propio | N8: Bueno | O8: CRÍTICO | P8: NO | R8: SI | S8: 2023 | T8: EXTERNO | U8: TDM | V8: 1057540-101-LE23 | W8: 2427846 | X8: 2 | AD8: √ | AJ8: X
A9: UTI - 9D | B9: Hospital Penco Lirquen | C9: Apoyo Terapéutico | D9: Alto Costo | E9: Ventilador mecánico no Invasivo | F9: Philips | G9: Trilogy 202 | H9: TV016091211 | I9: HPL24850 | J9: 2016 | K9: 8 | L9: 0 | M9: Propio | N9: Bueno | O9: CRÍTICO | P9: NO | R9: SI | S9: 2023 | T9: EXTERNO | U9: TDM | V9: 1057540-101-LE23 | W9: 2427846 | X9: 2 | AD9: √ | AJ9: X
A10: UTI - 1B | B10: Hospital Penco Lirquen | C10: Apoyo Terapéutico | D10: Alto Costo | E10: Ventilador mecánico Invasivo | F10: Philips | G10: Trilogy 100 | H10: TV11909271B | I10: HPL30385 | J10: 2020 | K10: 8 | L10: 4 | M10: Préstamo | N10: Bueno | O10: CRÍTICO | P10: NO | Q10: NO APLICA | R10: SI | S10: 2023 | T10: EXTERNO | U10: TDM | V10: 1057540-101-LE23 | W10: 2499246 | X10: 2 | AD10: √ | AJ10: X
A11: UTI - 1B | B11: Hospital Penco Lirquen | C11: Apoyo Terapéutico | D11: Alto Costo | E11: Ventilador mecánico Invasivo | F11: MECKics | G11: MV2000-EVO 5 | H11: MV2000UA1C0551 | I11: HPL30273 | J11: 2021 | K11: 8 | L11: 5 | M11: Préstamo | N11: Bueno | O11: CRÍTICO | P11: NO | Q11: NO APLICA | R11: SI | S11: 2023 | T11: EXTERNO | U11: TDM | V11: 1057540-101-LE23 | W11: 2499246 | X11: 2 | AD11: √ | AJ11: X
A12: UTI | B12: Hospital Penco Lirquen | C12: Monitoreo | D12: Alto Costo | E12: Monitor ECG transporte alta complejidad (pequeño adosado a 03740) | F12: Nihon Kohden | G12: BSM-1763K | H12: 8528 | J12: 2021 | K12: 8 | L12: 5 | M12: Préstamo | N12: Bueno | O12: CRÍTICO | P12: NO | Q12: NO APLICA | R12: SI | S12: 2023 | T12: INTERNO | U12: TECNICO EQM HPL | V12: NO APLICA | X12: 2 | AC12: √ | AI12: X
A13: UTI | B13: Hospital Penco Lirquen | C13: Monitoreo | D13: Alto Costo | E13: Monitor ECG transporte alta complejidad (pequeño adosado a 03740) | F13: Nihon Kohden | G13: BSM-1763K | H13: 08699 | I13: HPL30134 | J13: 2021 | K13: 8 | L13: 5 | M13: Préstamo | N13: Bueno | O13: CRÍTICO | P13: NO | Q13: NO APLICA | R13: SI | S13: 2023 | T13: INTERNO | U13: TECNICO EQM HPL | V13: NO APLICA | X13: 2 | AC13: √ | AI13: X
A14: UTI | B14: Hospital Penco Lirquen | C14: Monitoreo | D14: Alto Costo | E14: Monitor ECG transporte alta complejidad (pequeño adosado a 03740) | F14: Nihon Kohden | G14: BSM-1763K | H14: 08697 | I14: HPL30133 | J14: 2021 | K14: 8 | L14: 5 | M14: Préstamo | N14: Bueno | O14: CRÍTICO | P14: NO | Q14: NO APLICA | R14: SI | S14: 2023 | T14: INTERNO | U14: TECNICO EQM HPL | V14: NO APLICA | X14: 2 | AC14: √ | AI14: X
A15: UTI | B15: Hospital Penco Lirquen | C15: Monitoreo | D15: Alto Costo | E15: Monitor ECG transporte alta complejidad (pequeño adosado a 03740) | F15: Nihon Kohden | G15: BSM-1763K | H15: 08694 | I15: HPL30132 | J15: 2021 | K15: 8 | L15: 5 | M15: Préstamo | N15: Bueno | O15: CRÍTICO | P15: NO | Q15: NO APLICA | R15: SI | S15: 2023 | T15: INTERNO | U15: TECNICO EQM HPL | V15: NO APLICA | X15: 2 | AC15: √ | AI15: X
A16: UTI | B16: Hospital Penco Lirquen | C16: Monitoreo | D16: Alto Costo | E16: Monitor ECG alta complejidad | F16: Nihon Kohden | G16: CSM-1502 | H16: 03740 | I16: HPL30129 | J16: 2021 | K16: 8 | L16: 5 | M16: Préstamo | N16: Bueno | O16: CRÍTICO | P16: NO | Q16: NO APLICA | R16: SI | S16: 2023 | T16: INTERNO | U16: TECNICO EQM HPL | V16: NO APLICA | X16: 2 | AC16: √ | AI16: X
A17: UTI | B17: Hospital Penco Lirquen | C17: Monitoreo | D17: Alto Costo | E17: Monitor ECG alta complejidad | F17: Nihon Kohden | G17: CSM-1502 | H17: 03739 | I17: HPL30128 | J17: 2021 | K17: 8 | L17: 5 | M17: Propio | N17: Bueno | O17: CRÍTICO | P17: NO | Q17: NO APLICA | R17: SI | S17: 2023 | T17: INTERNO | U17: TECNICO EQM HPL | V17: NO APLICA | X17: 2 | AC17: √ | AI17: X
A18: UTI | B18: Hospital Penco Lirquen | C18: Monitoreo | D18: Alto Costo | E18: Monitor ECG alta complejidad | F18: Nihon Kohden | G18: CSM-1502 | H18: 03726 | I18: HPL30127 | J18: 2021 | K18: 8 | L18: 5 | M18: Préstamo | N18: Bueno | O18: CRÍTICO | P18: NO | Q18: NO APLICA | R18: SI | S18: 2023 | T18: INTERNO | U18: TECNICO EQM HPL | V18: NO APLICA | X18: 2 | AC18: √ | AI18: X
A19: UTI | B19: Hospital Penco Lirquen | C19: Monitoreo | D19: Alto Costo | E19: Monitor ECG alta complejidad | F19: Nihon Kohden | G19: CSM-1502 | H19: 03723 | I19: HPL30126 | J19: 2021 | K19: 8 | L19: 5 | M19: Propio | N19: Bueno | O19: CRÍTICO | P19: NO | Q19: NO APLICA | R19: SI | S19: 2023 | T19: INTERNO | U19: TECNICO EQM HPL | V19: NO APLICA | X19: 2 | AC19: √ | AI19: X
A20: UTI | B20: Hospital Penco Lirquen | C20: Monitoreo | D20: Alto Costo | E20: Monitor ECG alta complejidad | F20: Nihon Kohden | G20: CSM-1502 | H20: 03717 | I20: HPL30125 | J20: 2021 | K20: 8 | L20: 5 | M20: Préstamo | N20: Bueno | O20: CRÍTICO | P20: NO | Q20: NO APLICA | R20: SI | S20: 2023 | T20: INTERNO | U20: TECNICO EQM HPL | V20: NO APLICA | X20: 2 | AC20: √ | AI20: X
A21: UTI | B21: Hospital Penco Lirquen | C21: Monitoreo | D21: Alto Costo | E21: Monitor ECG alta complejidad | F21: Nihon Kohden | G21: CSM-1502 | H21: 03714 | I21: HPL30124 | J21: 2021 | K21: 8 | L21: 5 | M21: Préstamo | N21: Bueno | O21: CRÍTICO | P21: NO | Q21: NO APLICA | R21: SI | S21: 2023 | T21: INTERNO | U21: TECNICO EQM HPL | V21: NO APLICA | X21: 2 | AC21: √ | AI21: X
A22: UTI | B22: Hospital Penco Lirquen | C22: Monitoreo | D22: Alto Costo | E22: Monitor ECG transporte mediana complejidad (pequeño adosado a 03740) | F22: Nihon Kohden | G22: BSM-1763K | H22: 6678 | I22: HPL29879 | J22: 2020 | K22: 8 | L22: 4 | M22: Propio | N22: Bueno | O22: CRÍTICO | P22: NO | Q22: NO APLICA | R22: SI | S22: 2023 | T22: INTERNO | U22: TECNICO EQM HPL | V22: NO APLICA | X22: 2 | AC22: √ | AI22: X
A23: UTI | B23: Hospital Penco Lirquen | C23: Monitoreo | D23: Mediano Costo | E23: Monitor desfibrilador | F23: Zoll medical | G23: Serie R ALS | H23: AF20F118297 | I23: HPL30215 | J23: 2020 | K23: 8 | L23: 4 | M23: Propio | N23: Bueno | O23: CRÍTICO | P23: NO | Q23: NO APLICA | R23: SI | S23: 2023 | T23: INTERNO | U23: TECNICO EQM HPL | V23: NO APLICA | W23: - | X23: 2 | AC23: √ | AI23: X
A24: UTI | B24: Hospital Penco Lirquen | C24: Apoyo Terapéutico | D24: Alto Costo | E24: Ventilador mecánico Invasivo | F24: MECKics | G24: MV2000-EVO 5 | H24: MV2000UA1C0549 | I24: HPL30272 | J24: 2021 | K24: 8 | L24: 5 | M24: Préstamo | N24: Bueno | O24: CRÍTICO | P24: NO | Q24: NO APLICA | R24: SI | S24: 2023 | T24: CONTRATO | U24: TDM | V24: 1057540-101-LE23 | W24: 2499246 | X24: 2 | AD24: √ | AJ24: X
A25: Urgencia - 1B | B25: Hospital Penco Lirquen | C25: Apoyo Terapéutico | D25: Alto Costo | E25: Ventilador mecánico invasivo de transporte | F25: Drager | G25: Oxylog 3000 plus | H25: ASNH-0102 | I25: HPL30220 | J25: 2020 | K25: 8 | L25: 4 | M25: Propio | N25: Bueno | O25: CRÍTICO | P25: NO | Q25: NO APLICA | R25: SI | S25: 2023 | T25: CONTRATO | U25: TDM | V25: 1057540-101-LE23 | W25: 2499246 | X25: 2 | AD25: √ | AJ25: X
A26: Urgencia | B26: Hospital Penco Lirquen | C26: Monitoreo | D26: Mediano Costo | E26: Desfibrilador externo automático (DEA) | F26: NIHON KOHDEN | G26: AED-3100 | H26: 30594 | J26: 2023 | K26: 8 | L26: 7 | M26: Propio | N26: BUENO | O26: CRÍTICO | P26: SI | Q26: 45984 | R26: SI | S26: 2024 | T26: INTERNO | U26: TECNICO EQM HPL | V26: COLDAS 2023 (BLUMEDICAL) | W26: 0 | X26: 2 | AB26: √ | AH26: X
A27: Urgencia | B27: Hospital Penco Lirquen | C27: Monitoreo | D27: Mediano Costo | E27: Desfibrilador externo automático (DEA) | F27: NIHON KOHDEN | G27: AED-3100 | H27: 30574 | J27: 2023 | K27: 8 | L27: 7 | M27: Propio | N27: BUENO | O27: CRÍTICO | P27: SI | Q27: 45984 | R27: SI | S27: 2024 | T27: INTERNO | U27: TECNICO EQM HPL | V27: COLDAS 2023 (BLUMEDICAL) | W27: 0 | X27: 2 | AB27: √ | AH27: X
A28: Urgencia | B28: Hospital Penco Lirquen | C28: Monitoreo | D28: Mediano Costo | E28: Desfibrilador externo automático (DEA) | F28: NIHON KOHDEN | G28: AED-3100 | H28: 30584 | J28: 2023 | K28: 8 | L28: 7 | M28: Propio | N28: BUENO | O28: CRÍTICO | P28: SI | Q28: 45984 | R28: SI | S28: 2024 | T28: INTERNO | U28: TECNICO EQM HPL | V28: COLDAS 2023 (BLUMEDICAL) | W28: 0 | X28: 2 | AB28: √ | AH28: X
A29: Urgencia | B29: Hospital Penco Lirquen | C29: Monitoreo | D29: Mediano Costo | E29: Desfibrilador externo automático (DEA) | F29: NIHON KOHDEN | G29: AED-3100 | H29: 30559 | J29: 2023 | K29: 8 | L29: 7 | M29: Propio | N29: BUENO | O29: CRÍTICO | P29: SI | Q29: 45984 | R29: SI | S29: 2024 | T29: INTERNO | U29: TECNICO EQM HPL | V29: COLDAS 2023 (BLUMEDICAL) | W29: 0 | X29: 2 | AB29: √ | AH29: X
A30: Urgencia | B30: Hospital Penco Lirquen | C30: Monitoreo | D30: Mediano Costo | E30: Desfibrilador externo automático (DEA) | F30: NIHON KOHDEN | G30: AED-3100 | H30: 30583 | J30: 2023 | K30: 8 | L30: 7 | M30: Propio | N30: BUENO | O30: CRÍTICO | P30: SI | Q30: 45984 | R30: SI | S30: 2024 | T30: INTERNO | U30: TECNICO EQM HPL | V30: COLDAS 2023 (BLUMEDICAL) | W30: 0 | X30: 2 | AB30: √ | AH30: X
A31: Urgencia | B31: Hospital Penco Lirquen | C31: Monitoreo | D31: Mediano Costo | E31: Monitor ECG Baja Complejidad | F31: General Electric | G31: B20 | H31: SGF15151303WA | I31: HPL30370 | J31: 2016 | K31: 8 | L31: 0 | M31: Propio | N31: Bueno | O31: CRÍTICO | P31: NO | Q31: NO APLICA | R31: SI | S31: 2023 | T31: INTERNO | U31: TECNICO EQM HPL | V31: NO APLICA | X31: 2 | AC31: √ | AI31: X
A32: Urgencia | B32: Hospital Penco Lirquen | C32: Monitoreo | D32: Mediano Costo | E32: Monitor ECG Baja Complejidad | F32: General Electric | G32: B20 | H32: SGF15131190WA | I32: HPL30369 | J32: 2015 | K32: 8 | L32: -1 | M32: Propio | N32: Bueno | O32: CRÍTICO | P32: NO | Q32: NO APLICA | R32: SI | S32: 2023 | T32: INTERNO | U32: TECNICO EQM HPL | V32: NO APLICA | X32: 2 | AC32: √ | AI32: X
A33: Bodega de Equipos Médicos | B33: Hospital Penco Lirquen | C33: Monitoreo | D33: Mediano Costo | E33: Desfibrilador externo automático (DEA) | F33: Philips | G33: Heart Start | H33: A19K-06543 | I33: HPL30200 | J33: 2020 | K33: 8 | L33: 4 | M33: Propio | N33: Bueno | O33: CRÍTICO | P33: NO | Q33: NO APLICA | R33: SI | S33: 2023 | T33: INTERNO | U33: TECNICO EQM HPL | V33: NO APLICA | X33: 2 | AC33: √ | AI33: X
A34: Urgencia | B34: Hospital Penco Lirquen | C34: Monitoreo | D34: Mediano Costo | E34: Monitor ECG Baja Complejidad | F34: Fukuda Denshi | G34: Dinascope DSL-8001 | H34: 50200469 | I34: HPL30044 | J34: 2016 | K34: 8 | L34: 0 | M34: Propio | N34: Bueno | O34: CRÍTICO | P34: NO | Q34: NO APLICA | R34: SI | S34: 2023 | T34: INTERNO | U34: TECNICO EQM HPL | V34: NO APLICA | X34: 2 | AC34: √ | AI34: X
A35: Urgencia | B35: Hospital Penco Lirquen | C35: Monitoreo | D35: Mediano Costo | E35: Monitor ECG Baja Complejidad | F35: Fukuda Denshi | G35: Dinascope DSL-8001 | H35: 50200457 | I35: HPL30039 | J35: 2016 | K35: 8 | L35: 0 | M35: Propio | N35: Bueno | O35: CRÍTICO | P35: NO | Q35: NO APLICA | R35: SI | S35: 2023 | T35: INTERNO | U35: TECNICO EQM HPL | V35: NO APLICA | X35: 2 | AC35: √ | AI35: X
A36: Urgencia | B36: Hospital Penco Lirquen | C36: Monitoreo | D36: Mediano Costo | E36: Monitor ECG Baja Complejidad | F36: Fukuda Denshi | G36: Dinascope DSL-8001 | H36: 50200455 | I36: HPL30037 | J36: 2016 | K36: 8 | L36: 0 | M36: Propio | N36: Bueno | O36: CRÍTICO | P36: NO | Q36: NO APLICA | R36: SI | S36: 2023 | T36: INTERNO | U36: TECNICO EQM HPL | V36: NO APLICA | X36: 2 | AC36: √ | AI36: X
A37: Urgencia | B37: Hospital Penco Lirquen | C37: Monitoreo | D37: Mediano Costo | E37: Monitor ECG Baja Complejidad | F37: Fukuda Denshi | G37: Dinascope DSL-8001 | H37: 50200452 | I37: HPL30035 | J37: 2016 | K37: 8 | L37: 0 | M37: Propio | N37: Bueno | O37: CRÍTICO | P37: NO | Q37: NO APLICA | R37: SI | S37: 2023 | T37: INTERNO | U37: TECNICO EQM HPL | V37: NO APLICA | X37: 2 | AC37: √ | AI37: X
A38: Urgencia | B38: Hospital Penco Lirquen | C38: Monitoreo | D38: Mediano Costo | E38: Monitor ECG Baja Complejidad | F38: Fukuda Denshi | G38: Dinascope DSL-8001 | H38: 50200451 | I38: HPL30034 | J38: 2016 | K38: 8 | L38: 0 | M38: Propio | N38: Bueno | O38: CRÍTICO | P38: NO | Q38: NO APLICA | R38: SI | S38: 2023 | T38: INTERNO | U38: TECNICO EQM HPL | V38: NO APLICA | X38: 2 | AC38: √ | AI38: X
A39: Corta Estadia | B39: Hospital Penco Lirquen | C39: Monitoreo | D39: Mediano Costo | E39: Monitor ECG Baja Complejidad | F39: Fukuda Denshi | G39: Dinascope DSL-8001 | H39: 50200450 | I39: HPL25510 | J39: 2016 | K39: 8 | L39: 0 | M39: Propio | N39: Bueno | O39: CRÍTICO | P39: NO | Q39: NO APLICA | R39: SI | S39: 2023 | T39: INTERNO | U39: TECNICO EQM HPL | V39: NO APLICA | X39: 2 | AD39: √ | AJ39: X
A40: Corta Estadia | B40: Hospital Penco Lirquen | C40: Monitoreo | D40: Mediano Costo | E40: Monitor ECG Baja Complejidad | F40: Fukuda Denshi | G40: Dinascope DSL-8001 | H40: 50200468 | I40: HPL21701 | J40: 2016 | K40: 8 | L40: 0 | M40: Propio | N40: Bueno | O40: CRÍTICO | P40: NO | Q40: NO APLICA | R40: SI | S40: 2023 | T40: INTERNO | U40: TECNICO EQM HPL | V40: NO APLICA | X40: 2 | AD40: √ | AJ40: X
A41: Corta Estadia | B41: Hospital Penco Lirquen | C41: Monitoreo | D41: Mediano Costo | E41: Desfibrilador externo automático (DEA) | F41: Philips | G41: Heart Start | H41: A19K-06055 | I41: HPL30198 | J41: 2020 | K41: 8 | L41: 4 | M41: Propio | N41: Bueno | O41: CRÍTICO | P41: NO | Q41: NO APLICA | R41: SI | S41: 2023 | T41: INTERNO | U41: TECNICO EQM HPL | V41: NO APLICA | X41: 2 | AD41: √ | AJ41: X
...

Sheet Detalle3
A1: Detalles para Suma de COSTO ANUAL DE MANTENIMIENTO SEGÚN CONVENIO / PRECIO DE REFERENCIA MANTENIMIENTO ANUAL - AÑO INGRESO A PLAN DE MANTENIMIENTO (2023 / 2024 / 2025 / 2026): 2025
A3: SERVICIO CLÍNICO | B3: RECINTO | C3: CLASE | D3: SUBCLASE | E3: NOMBRE EQUIPO | F3: MARCA | G3: MODELO | H3: SERIE | I3: N° INVENTARIO | J3: AÑO DE ADQUISICIÓN | K3: VIDA ÚTIL | L3: VIDA ÚTIL RESIDUAL | M3: PROPIO / ARRIENDO / COMODATO | N3: ESTADO (BUENO / REGULAR / MALO / BAJA) | O3: CRÍTICO/ RELEVANTE / IM≥12 / NO APLICA | P3: EN GARANTÍA (SI / NO) | Q3: AÑO VENCIMIENTO GARANTÍA | R3: BAJO PLAN DE MANTENIMIENTO (SI / NO) | S3: AÑO INGRESO A PLAN DE MANTENIMIENTO (2023 / 2024 / 2025 / 2026) | T3: MANTENIMIENTO INTERNO O MANTENIMIENTO EXTERNO O CONTRATO | U3: NOMBRE DE PROVEEDOR O MANTENIMIENTO INTERNO | V3: ID CONVENIO DE MANTENIMIENTO / ID DE REFERENCIA / COTIZACIÓN DE REFERENCIA | W3: COSTO ANUAL DE MANTENIMIENTO SEGÚN CONVENIO / PRECIO DE REFERENCIA MANTENIMIENTO ANUAL | X3: FRECUENCIA ANUAL DE MANTENIMIENTO | Y3: ENERO | Z3: FEBRERO | AA3: MARZO | AB3: ABRIL | AC3: MAYO | AD3: JUNIO | AE3: JULIO | AF3: AGOSTO | AG3: SEPTIEMBRE | AH3: OCTUBRE | AI3: NOVIEMBRE | AJ3: DICIEMBRE
A4: Laboratorio | B4: Hospital Penco Lirquen | C4: Laboratorio/Farmac | D4: Alto Costo | E4: Analizador de orina | F4: Cobas | G4: U411 | H4: 20638 | J4: 2024 | K4: 8 | L4: 8 | M4: Comodato | N4: BUENO | O4: IM ≥ 12 | P4: NO | Q4: NO APLICA | R4: SI | S4: 2025 | T4: CONTRATO | U4: ROCHE | V4: 1057540-126-LP23 | W4: 0

Sheet TABLA CÁLCULO
A3: Etiquetas de fila | B3: Suma de FRECUENCIA ANUAL DE MANTENIMIENTO
A4: CRÍTICO | B4: 276
A5: IM ≥ 12 | B5: 378
A6: RELEVANTE | B6: 39
A7: NO APLICA | B7: 22
A8: Total general | B8: 715
B12: ENERO | C12: FEBRERO | D12: MARZO | E12: ABRIL | F12: MAYO | G12: JUNIO | H12: JULIO | I12: AGOSTO | J12: SEPTIEMBRE | K12: OCTUBRE | L12: NOVIEMBRE | M12: DICIEMBRE | O12: TOTAL MP PROGRAMADAS | P12: =+GETPIVOTDATA("FRECUENCIA ANUAL DE MANTENIMIENTO",$A$49,"AÑO INGRESO A PLAN DE MANTENIMIENTO (2023 / 2024 / 2025 / 2026)",2023)++GETPIVOTDATA("FRECUENCIA ANUAL DE MANTENIMIENTO",$A$49,"AÑO INGRESO A PLAN DE MANTENIMIENTO (2023 / 2024 / 2025 / 2026)",2024)+++GETPIVOTDATA("FRECUENCIA ANUAL DE MANTENIMIENTO",$A$49,"AÑO INGRESO A PLAN DE MANTENIMIENTO (2023 / 2024 / 2025 / 2026)",2025) -> 711
A13: N° MP EJECUTADAS | B13: =+COUNTIF('CATASTRO Y PLANIFICACIÓN MP'!Y16:Y151,"√") -> 4 | C13: =+COUNTIF('CATASTRO Y PLANIFICACIÓN MP'!Z16:Z151,"√") -> 0 | D13: =+COUNTIF('CATASTRO Y PLANIFICACIÓN MP'!AA16:AA151,"√") -> 3 | E13: =+COUNTIF('CATASTRO Y PLANIFICACIÓN MP'!AB16:AB151,"√") -> 0 | F13: =+COUNTIF('CATASTRO Y PLANIFICACIÓN MP'!AC16:AC151,"√") -> 0 | G13: =+COUNTIF('CATASTRO Y PLANIFICACIÓN MP'!AD16:AD151,"√") -> 0 | H13: =+COUNTIF('CATASTRO Y PLANIFICACIÓN MP'!AE16:AE151,"√") -> 0 | I13: =+COUNTIF('CATASTRO Y PLANIFICACIÓN MP'!AF16:AF151,"√") -> 0 | ... M13: =+COUNTIF('CATASTRO Y PLANIFICACIÓN MP'!AJ16:AJ151,"√") -> 0 | O13: TOTAL MP EJECUTADAS | P13: =+SUM(B13:M13) -> 7 | R13: X | S13: PROGRAMADO | U13: CRÍTICO | W13: SI | Y13: 2025 | AA13: INTERNO | AC13: 1 | AE13: PROPIO | AF13: BUENO
A14: N° MP REPROGRAMADAS | B14: =+COUNTIF('CATASTRO Y PLANIFICACIÓN MP'!#REF!,"ꓣ") -> #REF! | C14: =+COUNTIF('CATASTRO Y PLANIFICACIÓN MP'!#REF!,"ꓣ") -> #REF! | D14: =+COUNTIF('CATASTRO Y PLANIFICACIÓN MP'!#REF!,"ꓣ") -> #REF! | E14: =+COUNTIF('CATASTRO Y PLANIFICACIÓN MP'!#REF!,"ꓣ") -> #REF! | F14: =+COUNTIF('CATASTRO Y PLANIFICACIÓN MP'!#REF!,"ꓣ") -> #REF! | G14: =+COUNTIF('CATASTRO Y PLANIFICACIÓN MP'!#REF!,"ꓣ") -> #REF! | H14: =+COUNTIF('CATASTRO Y PLANIFICACIÓN MP'!#REF!,"ꓣ") -> #REF! | I14: =+COUNTIF('CATASTRO Y PLANIFICACIÓN MP'!#REF!,"ꓣ") -> #REF! | ... M14: =+COUNTIF('CATASTRO Y PLANIFICACIÓN MP'!#REF!,"ꓣ") -> #REF! | O14: TOTAL MP REPROGRAMADAS | P14: =+SUM(B14:M14) -> #REF! | R14: √ | S14: REALIZADO | U14: RELEVANTE | W14: NO | Y14: 2026 | AA14: EXTERNO | AC14: 2 | AE14: ARRIENDO | AF14: REGULAR
